{
  "affected_release": null,
  "package_state": [
    {
      "product_name": "Red Hat Enterprise Linux 6",
      "fix_state": "Out of support scope",
      "package_name": "kernel",
      "cpe": "cpe:/o:redhat:enterprise_linux:6"
    },
    {
      "product_name": "Red Hat Enterprise Linux 7",
      "fix_state": "Out of support scope",
      "package_name": "kernel",
      "cpe": "cpe:/o:redhat:enterprise_linux:7"
    },
    {
      "product_name": "Red Hat Enterprise Linux 7",
      "fix_state": "Out of support scope",
      "package_name": "kernel-rt",
      "cpe": "cpe:/o:redhat:enterprise_linux:7"
    },
    {
      "product_name": "Red Hat Enterprise Linux 8",
      "fix_state": "Out of support scope",
      "package_name": "kernel",
      "cpe": "cpe:/o:redhat:enterprise_linux:8"
    },
    {
      "product_name": "Red Hat Enterprise Linux 8",
      "fix_state": "Out of support scope",
      "package_name": "kernel-rt",
      "cpe": "cpe:/o:redhat:enterprise_linux:8"
    },
    {
      "product_name": "Red Hat Enterprise Linux 9",
      "fix_state": "Affected",
      "package_name": "kernel",
      "cpe": "cpe:/o:redhat:enterprise_linux:9"
    },
    {
      "product_name": "Red Hat Enterprise Linux 9",
      "fix_state": "Affected",
      "package_name": "kernel-rt",
      "cpe": "cpe:/o:redhat:enterprise_linux:9"
    }
  ],
  "threat_severity": "Moderate",
  "public_date": "2025-02-26T00:00:00Z",
  "bugzilla": {
    "description": "kernel: tcp: Fix a data-race around sysctl_tcp_ecn_fallback.",
    "id": "2348249",
    "url": "https://bugzilla.redhat.com/show_bug.cgi?id=2348249"
  },
  "cvss": {
    "cvss_base_score": "",
    "cvss_scoring_vector": "",
    "status": ""
  },
  "cvss3": {
    "cvss3_base_score": "5.5",
    "cvss3_scoring_vector": "CVSS:3.1/AV:L/AC:L/PR:L/UI:N/S:U/C:N/I:N/A:H",
    "status": "draft"
  },
  "iava": "",
  "cwe": "",
  "statement": "",
  "acknowledgement": "",
  "name": "CVE-2022-49630",
  "document_distribution": "",
  "details": [
    "In the Linux kernel, the following vulnerability has been resolved:\ntcp: Fix a data-race around sysctl_tcp_ecn_fallback.\nWhile reading sysctl_tcp_ecn_fallback, it can be changed concurrently.\nThus, we need to add READ_ONCE() to its reader."
  ],
  "references": [
    "https://www.cve.org/CVERecord?id=CVE-2022-49630\nhttps://nvd.nist.gov/vuln/detail/CVE-2022-49630\nhttps://lore.kernel.org/linux-cve-announce/2025022616-CVE-2022-49630-71c3@gregkh/T"
  ]
}